24/04/22 (09:08:44) | ERROR: [Errno 2] No such file or directory: '/home/putin/.config/bpytop/themes'
Traceback (most recent call last):
  File "/usr/bin/bpytop", line 1319, in refresh
    for f in os.listdir(d):
FileNotFoundError: [Errno 2] No such file or directory: '/home/putin/.config/bpytop/themes'
12/06/22 (01:10:31) | ERROR: [Errno 2] No such file or directory: '/home/putin/.config/bpytop/themes'
Traceback (most recent call last):
  File "/usr/bin/bpytop", line 1357, in refresh
    for f in os.listdir(d):
FileNotFoundError: [Errno 2] No such file or directory: '/home/putin/.config/bpytop/themes'
11/07/22 (01:40:30) | ERROR: [Errno 2] No such file or directory: '/home/putin/.config/bpytop/themes'
Traceback (most recent call last):
  File "/sbin/bpytop", line 1357, in refresh
    for f in os.listdir(d):
FileNotFoundError: [Errno 2] No such file or directory: '/home/putin/.config/bpytop/themes'
11/07/22 (18:42:52) | ERROR: <urlopen error [Errno -3] Temporary failure in name resolution>
Traceback (most recent call last):
  File "/usr/lib/python3.10/urllib/request.py", line 1348, in do_open
    h.request(req.get_method(), req.selector, req.data, headers,
  File "/usr/lib/python3.10/http/client.py", line 1282, in request
    self._send_request(method, url, body, headers, encode_chunked)
  File "/usr/lib/python3.10/http/client.py", line 1328, in _send_request
    self.endheaders(body, encode_chunked=encode_chunked)
  File "/usr/lib/python3.10/http/client.py", line 1277, in endheaders
    self._send_output(message_body, encode_chunked=encode_chunked)
  File "/usr/lib/python3.10/http/client.py", line 1037, in _send_output
    self.send(msg)
  File "/usr/lib/python3.10/http/client.py", line 975, in send
    self.connect()
  File "/usr/lib/python3.10/http/client.py", line 1447, in connect
    super().connect()
  File "/usr/lib/python3.10/http/client.py", line 941, in connect
    self.sock = self._create_connection(
  File "/usr/lib/python3.10/socket.py", line 824, in create_connection
    for res in getaddrinfo(host, port, 0, SOCK_STREAM):
  File "/usr/lib/python3.10/socket.py", line 955, in getaddrinfo
    for res in _socket.getaddrinfo(host, port, family, type, proto, flags):
socket.gaierror: [Errno -3] Temporary failure in name resolution

During handling of the above exception, another exception occurred:

Traceback (most recent call last):
  File "/usr/bin/bpytop", line 5029, in _checker
    with urllib.request.urlopen("https://github.com/aristocratos/bpytop/raw/master/bpytop.py", timeout=5) as source: # type: ignore
  File "/usr/lib/python3.10/urllib/request.py", line 216, in urlopen
    return opener.open(url, data, timeout)
  File "/usr/lib/python3.10/urllib/request.py", line 519, in open
    response = self._open(req, data)
  File "/usr/lib/python3.10/urllib/request.py", line 536, in _open
    result = self._call_chain(self.handle_open, protocol, protocol +
  File "/usr/lib/python3.10/urllib/request.py", line 496, in _call_chain
    result = func(*args)
  File "/usr/lib/python3.10/urllib/request.py", line 1391, in https_open
    return self.do_open(http.client.HTTPSConnection, req,
  File "/usr/lib/python3.10/urllib/request.py", line 1351, in do_open
    raise URLError(err)
urllib.error.URLError: <urlopen error [Errno -3] Temporary failure in name resolution>
11/07/22 (18:42:52) | ERROR: [Errno 2] No such file or directory: '/home/putin/.config/bpytop/themes'
Traceback (most recent call last):
  File "/usr/bin/bpytop", line 1357, in refresh
    for f in os.listdir(d):
FileNotFoundError: [Errno 2] No such file or directory: '/home/putin/.config/bpytop/themes'
12/07/22 (02:56:28) | ERROR: [Errno 2] No such file or directory: '/home/putin/.config/bpytop/themes'
Traceback (most recent call last):
  File "/usr/bin/bpytop", line 1357, in refresh
    for f in os.listdir(d):
FileNotFoundError: [Errno 2] No such file or directory: '/home/putin/.config/bpytop/themes'
12/08/22 (18:36:38) | ERROR: [Errno 2] No such file or directory: '/home/putin/.config/bpytop/themes'
Traceback (most recent call last):
  File "/sbin/bpytop", line 1357, in refresh
    for f in os.listdir(d):
FileNotFoundError: [Errno 2] No such file or directory: '/home/putin/.config/bpytop/themes'
23/08/22 (16:07:12) | ERROR: [Errno 2] No such file or directory: '/home/putin/.config/bpytop/themes'
Traceback (most recent call last):
  File "/sbin/bpytop", line 1357, in refresh
    for f in os.listdir(d):
FileNotFoundError: [Errno 2] No such file or directory: '/home/putin/.config/bpytop/themes'
28/08/22 (19:15:14) | ERROR: [Errno 2] No such file or directory: '/home/putin/.config/bpytop/themes'
Traceback (most recent call last):
  File "/sbin/bpytop", line 1357, in refresh
    for f in os.listdir(d):
FileNotFoundError: [Errno 2] No such file or directory: '/home/putin/.config/bpytop/themes'
28/08/22 (19:36:53) | ERROR: [Errno 2] No such file or directory: '/home/putin/.config/bpytop/themes'
Traceback (most recent call last):
  File "/sbin/bpytop", line 1357, in refresh
    for f in os.listdir(d):
FileNotFoundError: [Errno 2] No such file or directory: '/home/putin/.config/bpytop/themes'
28/08/22 (22:23:41) | ERROR: [Errno 2] No such file or directory: '/home/putin/.config/bpytop/themes'
Traceback (most recent call last):
  File "/sbin/bpytop", line 1357, in refresh
    for f in os.listdir(d):
FileNotFoundError: [Errno 2] No such file or directory: '/home/putin/.config/bpytop/themes'
11/09/22 (00:15:53) | ERROR: [Errno 2] No such file or directory: '/home/putin/.config/bpytop/themes'
Traceback (most recent call last):
  File "/usr/bin/bpytop", line 1357, in refresh
    for f in os.listdir(d):
FileNotFoundError: [Errno 2] No such file or directory: '/home/putin/.config/bpytop/themes'
11/09/22 (00:17:11) | ERROR: [Errno 2] No such file or directory: '/home/putin/.config/bpytop/themes'
Traceback (most recent call last):
  File "/usr/bin/bpytop", line 1357, in refresh
    for f in os.listdir(d):
FileNotFoundError: [Errno 2] No such file or directory: '/home/putin/.config/bpytop/themes'
11/09/22 (00:19:53) | ERROR: [Errno 2] No such file or directory: '/home/putin/.config/bpytop/themes'
Traceback (most recent call last):
  File "/usr/bin/bpytop", line 1357, in refresh
    for f in os.listdir(d):
FileNotFoundError: [Errno 2] No such file or directory: '/home/putin/.config/bpytop/themes'
17/09/22 (22:40:24) | ERROR: [Errno 2] No such file or directory: '/home/putin/.config/bpytop/themes'
Traceback (most recent call last):
  File "/usr/bin/bpytop", line 1357, in refresh
    for f in os.listdir(d):
FileNotFoundError: [Errno 2] No such file or directory: '/home/putin/.config/bpytop/themes'
20/09/22 (03:11:53) | ERROR: [Errno 2] No such file or directory: '/home/putin/.config/bpytop/themes'
Traceback (most recent call last):
  File "/usr/bin/bpytop", line 1357, in refresh
    for f in os.listdir(d):
FileNotFoundError: [Errno 2] No such file or directory: '/home/putin/.config/bpytop/themes'
20/09/22 (03:12:10) | ERROR: [Errno 2] No such file or directory: '/home/putin/.config/bpytop/themes'
Traceback (most recent call last):
  File "/usr/bin/bpytop", line 1357, in refresh
    for f in os.listdir(d):
FileNotFoundError: [Errno 2] No such file or directory: '/home/putin/.config/bpytop/themes'
27/12/22 (19:59:33) | ERROR: [Errno 2] No such file or directory: '/home/putin/.config/bpytop/themes'
Traceback (most recent call last):
  File "/usr/bin/bpytop", line 1357, in refresh
    for f in os.listdir(d):
FileNotFoundError: [Errno 2] No such file or directory: '/home/putin/.config/bpytop/themes'
07/05/23 (01:13:04) | ERROR: [Errno 2] No such file or directory: '/home/putin/.config/bpytop/themes'
Traceback (most recent call last):
  File "/usr/bin/bpytop", line 1357, in refresh
    for f in os.listdir(d):
FileNotFoundError: [Errno 2] No such file or directory: '/home/putin/.config/bpytop/themes'
27/04/24 (20:04:36) | ERROR: [Errno 2] No such file or directory: '/home/putin/.config/bpytop/themes'
Traceback (most recent call last):
  File "/sbin/bpytop", line 1357, in refresh
    for f in os.listdir(d):
             ^^^^^^^^^^^^^
FileNotFoundError: [Errno 2] No such file or directory: '/home/putin/.config/bpytop/themes'
27/04/24 (23:24:28) | ERROR: [Errno 2] No such file or directory: '/home/putin/.config/bpytop/themes'
Traceback (most recent call last):
  File "/sbin/bpytop", line 1357, in refresh
    for f in os.listdir(d):
             ^^^^^^^^^^^^^
FileNotFoundError: [Errno 2] No such file or directory: '/home/putin/.config/bpytop/themes'
