14/11/20 (17:31:54) | ERROR: <urlopen error [Errno -3] Temporary failure in name resolution>
Traceback (most recent call last):
  File "/usr/lib/python3.8/urllib/request.py", line 1350, in do_open
    h.request(req.get_method(), req.selector, req.data, headers,
  File "/usr/lib/python3.8/http/client.py", line 1255, in request
    self._send_request(method, url, body, headers, encode_chunked)
  File "/usr/lib/python3.8/http/client.py", line 1301, in _send_request
    self.endheaders(body, encode_chunked=encode_chunked)
  File "/usr/lib/python3.8/http/client.py", line 1250, in endheaders
    self._send_output(message_body, encode_chunked=encode_chunked)
  File "/usr/lib/python3.8/http/client.py", line 1010, in _send_output
    self.send(msg)
  File "/usr/lib/python3.8/http/client.py", line 950, in send
    self.connect()
  File "/usr/lib/python3.8/http/client.py", line 1417, in connect
    super().connect()
  File "/usr/lib/python3.8/http/client.py", line 921, in connect
    self.sock = self._create_connection(
  File "/usr/lib/python3.8/socket.py", line 787, in create_connection
    for res in getaddrinfo(host, port, 0, SOCK_STREAM):
  File "/usr/lib/python3.8/socket.py", line 918, in getaddrinfo
    for res in _socket.getaddrinfo(host, port, family, type, proto, flags):
socket.gaierror: [Errno -3] Temporary failure in name resolution

During handling of the above exception, another exception occurred:

Traceback (most recent call last):
  File "/usr/bin/bpytop", line 4302, in _checker
    with urllib.request.urlopen("https://github.com/aristocratos/bpytop/raw/master/bpytop.py", timeout=5) as source: # type: ignore
  File "/usr/lib/python3.8/urllib/request.py", line 222, in urlopen
    return opener.open(url, data, timeout)
  File "/usr/lib/python3.8/urllib/request.py", line 525, in open
    response = self._open(req, data)
  File "/usr/lib/python3.8/urllib/request.py", line 542, in _open
    result = self._call_chain(self.handle_open, protocol, protocol +
  File "/usr/lib/python3.8/urllib/request.py", line 502, in _call_chain
    result = func(*args)
  File "/usr/lib/python3.8/urllib/request.py", line 1393, in https_open
    return self.do_open(http.client.HTTPSConnection, req,
  File "/usr/lib/python3.8/urllib/request.py", line 1353, in do_open
    raise URLError(err)
urllib.error.URLError: <urlopen error [Errno -3] Temporary failure in name resolution>
04/03/21 (21:10:51) | WARNING: Config key "cpu_sensor" does not contain an available sensor!
04/03/21 (21:10:51) | ERROR: [Errno 2] No such file or directory: '/home/pitin/.config/bpytop/themes'
Traceback (most recent call last):
  File "/usr/bin/bpytop", line 1327, in refresh
    for f in os.listdir(d):
FileNotFoundError: [Errno 2] No such file or directory: '/home/pitin/.config/bpytop/themes'
06/03/21 (11:55:22) | ERROR: [Errno 2] No such file or directory: '/home/pitin/.config/bpytop/themes'
Traceback (most recent call last):
  File "/usr/bin/bpytop", line 1327, in refresh
    for f in os.listdir(d):
FileNotFoundError: [Errno 2] No such file or directory: '/home/pitin/.config/bpytop/themes'
06/03/21 (11:56:29) | ERROR: [Errno 2] No such file or directory: '/home/pitin/.config/bpytop/themes'
Traceback (most recent call last):
  File "/usr/bin/bpytop", line 1327, in refresh
    for f in os.listdir(d):
FileNotFoundError: [Errno 2] No such file or directory: '/home/pitin/.config/bpytop/themes'
22/06/21 (19:44:24) | ERROR: [Errno 2] No such file or directory: '/home/putin/.config/bpytop/themes'
Traceback (most recent call last):
  File "/usr/bin/bpytop", line 1337, in refresh
    for f in os.listdir(d):
FileNotFoundError: [Errno 2] No such file or directory: '/home/putin/.config/bpytop/themes'
26/06/21 (18:42:01) | ERROR: [Errno 2] No such file or directory: '/home/putin/.config/bpytop/themes'
Traceback (most recent call last):
  File "/usr/bin/bpytop", line 1337, in refresh
    for f in os.listdir(d):
FileNotFoundError: [Errno 2] No such file or directory: '/home/putin/.config/bpytop/themes'
06/08/21 (16:57:58) | ERROR: [Errno 2] No such file or directory: '/home/putin/.config/bpytop/themes'
Traceback (most recent call last):
  File "/usr/bin/bpytop", line 1337, in refresh
    for f in os.listdir(d):
FileNotFoundError: [Errno 2] No such file or directory: '/home/putin/.config/bpytop/themes'
18/08/21 (23:52:25) | ERROR: [Errno 2] No such file or directory: '/home/putin/.config/bpytop/themes'
Traceback (most recent call last):
  File "/usr/bin/bpytop", line 1337, in refresh
    for f in os.listdir(d):
FileNotFoundError: [Errno 2] No such file or directory: '/home/putin/.config/bpytop/themes'
19/08/21 (23:49:14) | ERROR: [Errno 2] No such file or directory: '/home/putin/.config/bpytop/themes'
Traceback (most recent call last):
  File "/usr/bin/bpytop", line 1337, in refresh
    for f in os.listdir(d):
FileNotFoundError: [Errno 2] No such file or directory: '/home/putin/.config/bpytop/themes'
20/08/21 (22:46:25) | ERROR: [Errno 2] No such file or directory: '/home/putin/.config/bpytop/themes'
Traceback (most recent call last):
  File "/usr/bin/bpytop", line 1337, in refresh
    for f in os.listdir(d):
FileNotFoundError: [Errno 2] No such file or directory: '/home/putin/.config/bpytop/themes'
24/08/21 (17:00:26) | ERROR: [Errno 2] No such file or directory: '/home/putin/.config/bpytop/themes'
Traceback (most recent call last):
  File "/usr/bin/bpytop", line 1337, in refresh
    for f in os.listdir(d):
FileNotFoundError: [Errno 2] No such file or directory: '/home/putin/.config/bpytop/themes'
24/08/21 (17:00:34) | ERROR: [Errno 2] No such file or directory: '/home/putin/.config/bpytop/themes'
Traceback (most recent call last):
  File "/usr/bin/bpytop", line 1337, in refresh
    for f in os.listdir(d):
FileNotFoundError: [Errno 2] No such file or directory: '/home/putin/.config/bpytop/themes'
24/08/21 (17:00:56) | ERROR: [Errno 2] No such file or directory: '/home/putin/.config/bpytop/themes'
Traceback (most recent call last):
  File "/usr/bin/bpytop", line 1337, in refresh
    for f in os.listdir(d):
FileNotFoundError: [Errno 2] No such file or directory: '/home/putin/.config/bpytop/themes'
24/08/21 (17:01:00) | ERROR: [Errno 2] No such file or directory: '/home/putin/.config/bpytop/themes'
Traceback (most recent call last):
  File "/usr/bin/bpytop", line 1337, in refresh
    for f in os.listdir(d):
FileNotFoundError: [Errno 2] No such file or directory: '/home/putin/.config/bpytop/themes'
24/08/21 (17:01:09) | ERROR: [Errno 2] No such file or directory: '/home/putin/.config/bpytop/themes'
Traceback (most recent call last):
  File "/usr/bin/bpytop", line 1337, in refresh
    for f in os.listdir(d):
FileNotFoundError: [Errno 2] No such file or directory: '/home/putin/.config/bpytop/themes'
